Workbook

Sheet Mode d'emploi
A1: IGPDE - Formation 102638 - Grille d'audit 13 Easy Checks du W3C
A4: Objet
B5: Grille de diagnostic rapide sur les 13 Easy Checks du W3C WAI, alignée sur le RGAA 4.1.2.
A7: Avertissement
B8: Cet outil est un outil de SENSIBILISATION et de pré-diagnostic.
B9: Il ne remplace en aucun cas un audit RGAA formel (106 critères sur 13 thématiques) réalisé par un expert certifié.
B10: Le « Taux de conformité Easy Checks » calculé ici n'est PAS le taux de conformité RGAA officiel publié en déclaration d'accessibilité.
A12: Préparer l'audit
A13: 1. | B13: Choisir 1 à 5 pages représentatives (accueil, formulaire, résultats de recherche, contact).
A14: 2. | B14: Ouvrir dans un navigateur récent (Chrome, Firefox, Edge).
A15: 3. | B15: Installer la boîte à outils a11y : https://a11y-tools.netlify.app/
A16: 4. | B16: Prévoir un casque audio et un lecteur d'écran (VoiceOver sur Mac, NVDA sur Windows).
A18: Pour chaque critère, renseigner
A19: 1. | B19: Verdict : C (Conforme), NC (Non conforme), NA (Non applicable).
A20: 2. | B20: Sévérité : Bloquant, Gênant, Mineur, Info (uniquement si NC).
A21: 3. | B21: Constat : ce que vous avez observé concrètement.
A22: 4. | B22: Correctif : action que l'équipe web devra mener.
A23: 5. | B23: Preuve : URL, capture d'écran, sélecteur CSS, extrait de code.
A25: Règle pour l'exercice en binômes
A26: 1. | B26: Les pages sont réparties entre plusieurs groupes : chaque binôme audite uniquement les pages attribuées.
A27: 2. | B27: Pour une page donnée, une seule occurrence correctement prouvée suffit à renseigner NC sur le critère ciblé.
A28: 3. | B28: Les autres occurrences éventuelles sont des bonus utiles pour la restitution, mais elles ne sont pas exigées pour invalider le critère.
A30: Conventions de verdict
A31: C | B31: Conforme - le critère est respecté sans réserve.
A32: NC | B32: Non conforme - un défaut objectif a été constaté.
A33: NA | B33: Non applicable - le critère ne s'applique pas à cette page.
A35: Conventions de sévérité
A36: Bloquant | B36: Certaines personnes sont exclues du service.
A37: Gênant | B37: Certaines personnes ont des difficultés importantes.
A38: Mineur | B38: L'ergonomie peut être améliorée mais l'accès reste possible.
A39: Info | B39: Observation à des fins d'amélioration, sans blocage.
A41: Onglets du classeur
B42: Mode d'emploi : ce document.
B43: Grille vierge : 13 critères à remplir pour la page auditée.
B44: Exemple : audit illustratif sur une page type.
B45: Synthèse : décompte automatique et taux de conformité multi-pages.
A47: Références
B48: W3C Easy Checks : https://www.w3.org/WAI/test-evaluate/easy-checks/
B49: RGAA 4.1.2 : https://accessibilite.numerique.gouv.fr/
B50: Inspiration méthodologique : grille Easy Checks de beta.gouv.fr.

Sheet Échantillon RGAA
A1: Échantillon RGAA 4.1.2 - pages obligatoires
A3: La méthode technique du RGAA 4.1.2 impose un échantillon minimal de pages à auditer pour déclarer la conformité d'un site public.
A4: Les 9 premières pages sont obligatoires (sauf si la fonction n'existe pas : noter NA).
A5: Les pages 10 à 12 sont représentatives : au moins une page par type de gabarit (article, formulaire, liste).
A6: Source officielle : https://accessibilite.numerique.gouv.fr/
A8: N | B8: Type de page | C8: Caractère | D8: URL à auditer | E8: Commentaire
A9: 1 | B9: Page d'accueil | C9: Obligatoire | E9: Toujours auditée, même si une page de connexion précède.
A10: 2 | B10: Page « Mentions légales » | C10: Obligatoire | E10: Page réglementaire, présente sur tous les sites publics.
A11: 3 | B11: Déclaration d'accessibilité | C11: Obligatoire | E11: Page qui décrit l'état de conformité du site (article 47 de la loi de 2005).
A12: 4 | B12: Page « Plan du site » | C12: Obligatoire | E12: Si présente ; sinon, mentionner NA dans l'audit.
A13: 5 | B13: Page « Contact » | C13: Obligatoire | E13: Formulaire ou page avec coordonnées de l'organisme.
A14: 6 | B14: Page « Aide » / FAQ | C14: Obligatoire | E14: Si présente ; sinon, mentionner NA.
A15: 7 | B15: Page d'authentification / connexion | C15: Obligatoire si existante | E15: Auditée uniquement si le site propose un espace personnel.
A16: 8 | B16: Page de résultats de recherche | C16: Obligatoire si moteur | E16: Auditée avec un jeu de résultats réel, pas une page vide.
A17: 9 | B17: Document téléchargeable (PDF, DOCX, ODT) | C17: Obligatoire si présent | E17: Au moins un document représentatif. Attention : les 13 Easy Checks web ne couvrent qu'en partie les documents. Pour un audit complet, utiliser PAC 2024 (gratuit), Acrobat Pro ou Axes4.
A18: 10 | B18: Page type : article, actualité ou contenu rédactionnel | C18: Représentative | E18: Une page représentative du gabarit éditorial le plus fréquent.
A19: 11 | B19: Page type : formulaire de démarche ou saisie multi-étape | C19: Représentative | E19: Processus critique (inscription, demande, déclaration).
A20: 12 | B20: Page type : liste / rubrique / résultats de navigation | C20: Représentative | E20: Gabarit qui affiche plusieurs éléments triés ou filtrés.
A22: Légende
B23: Obligatoire | C23: Présente sur tout site public, à auditer systématiquement.
B24: Obligatoire si existante | C24: À auditer uniquement si la fonction existe sur le site.
B25: Représentative | C25: Échantillon représentatif des gabarits du site.

Sheet 1. Accueil
A1: Auditeur / auditrice
A2: Date de l'audit
A3: URL de la page auditée
A4: Intitulé de la page | D4: Page d'accueil
A5: Navigateur et version
A6: Outils utilisés
A8: N | B8: Easy Check | C8: WCAG 2.2 | D8: RGAA 4.1.2 | E8: Méthode de test | F8: Ce qu'il faut vérifier | G8: Verdict | H8: Sévérité | I8: Constat | J8: Correctif suggéré | K8: Preuve (URL, sélecteur, capture)
A9: 1 | B9: Alternatives textuelles des images | C9: 1.1.1 | D9: 1.1, 1.2, 1.3, 1.6, 1.7, 1.8, 1.9 | E9: Bookmarklet « Check images », ou clic droit Inspecter sur chaque image. | F9: Alt présent. Alt vide pour les décoratives. Alt explicite (action attendue) pour les images-liens. Description longue pour les graphiques et schémas complexes.
A10: 2 | B10: Titre de page | C10: 2.4.2 | D10: 8.5, 8.6 | E10: Survoler l'onglet du navigateur, lire la balise <title>. | F10: Titre présent, unique par page, information prioritaire placée en premier (front-loading).
A11: 3 | B11: Titres et hiérarchie | C11: 1.3.1, 2.4.6 | D11: 9.1 | E11: Extension HeadingsMap ou bookmarklet « Check headings ». | F11: Un seul <h1> par page. Niveaux emboîtés sans saut (H1 vers H2 vers H3). Titres balisés <h1> à <h6>, pas seulement stylés en CSS.
A12: 4 | B12: Contraste des couleurs | C12: 1.4.3, 1.4.11 | D12: 3.2, 3.3 | E12: Pipette DevTools, WebAIM Contrast Checker, Colour Contrast Analyser (CCA). | F12: Texte normal : ratio >= 4,5:1. Texte large (18 pt ou 14 pt gras) : ratio >= 3:1. Composants graphiques porteurs d'information : >= 3:1.
A13: 5 | B13: Lien d'évitement | C13: 2.4.1 | D13: 12.7 | E13: Charger la page, appuyer une fois sur Tab. | F13: 1er élément focus = lien « Aller au contenu ». Visible au focus même s'il est masqué par défaut. Ancre valide (#contenu, #main).
A14: 6 | B14: Focus et navigation clavier | C14: 2.4.7, 2.1.1, 2.1.2, 2.4.3 | D14: 10.7, 12.13, 12.14, 10.3 | E14: Cacher la souris. Parcours complet au clavier uniquement (Tab, Maj+Tab, Entrée, Espace, flèches). | F14: Focus visible sur tous les éléments interactifs. Ordre de tabulation logique. Pas de piège clavier. État (coché, développé, sélectionné) annoncé.
A15: 7 | B15: Langue de la page | C15: 3.1.1, 3.1.2 | D15: 8.3, 8.4 | E15: Clic droit « Afficher le code source », chercher <html lang="…">. | F15: Attribut lang présent avec code ISO 639 (fr, en, de…). Passages dans une autre langue balisés <span lang="…">.
A16: 8 | B16: Zoom à 200 % | C16: 1.4.4, 1.4.10 | D16: 10.4, 10.11 | E16: Ctrl + (Cmd + sur Mac) jusqu'à 200 %, parcourir la page complète. | F16: Aucun texte coupé ni superposé. Pas de défilement horizontal forcé. Menus, boutons et formulaires restent utilisables.
A17: 9 | B17: Sous-titres vidéo | C17: 1.2.2 | D17: 4.3, 4.4 | E17: Lancer la vidéo, couper le son, activer les sous-titres (bouton CC). | F17: Sous-titres synchronisés présents. Paroles + informations sonores importantes ((rires), (sonnerie)). Qualité éditoriale (pas auto-générés non relus).
A18: 10 | B18: Transcriptions audio et vidéo | C18: 1.2.1 | D18: 4.1, 4.2 | E18: Chercher un lien « Transcription » ou « Lire le texte » visible près du média. | F18: Transcription accessible à un clic. Complète (paroles + bruits utiles). Navigable (titres, paragraphes).
A19: 11 | B19: Audiodescription | C19: 1.2.3, 1.2.5 | D19: 4.5, 4.6 | E19: Vérifier la présence d'une piste audiodécrite (bouton AD). | F19: AD disponible pour les vidéos informatives à contenu visuel essentiel. Intercalée dans les silences, sans couvrir les dialogues.
A20: 12 | B20: Étiquettes de formulaire | C20: 3.3.2, 1.3.1, 2.5.3 | D20: 11.1, 11.2, 11.3 | E20: Cliquer sur le libellé (le focus doit sauter dans le champ). Tester au lecteur d'écran. | F20: Étiquette visible et persistante. Association <label for="…"> ou aria-labelledby. Placeholder = exemple, jamais étiquette unique. Fieldset/legend pour les groupes (radios, cases).
A21: 13 | B21: Champs obligatoires et erreurs | C21: 3.3.2, 3.3.1, 3.3.3 | D21: 11.10, 11.11 | E21: Soumettre un formulaire incomplet. Écouter l'annonce par le lecteur d'écran. | F21: Obligatoires indiqués textuellement et par astérisque. Légende « * champ obligatoire » présente. Messages d'erreur qui identifient le champ par son libellé.
A24: Synthèse de la page
A25: Conforme (C) | F25: =COUNTIF(G9:G21,"C")
A26: Non conforme (NC) | F26: =COUNTIF(G9:G21,"NC")
A27: Non applicable (NA) | F27: =COUNTIF(G9:G21,"NA")
A28: Taux de conformité Easy Checks | F28: =IFERROR(COUNTIF(G9:G21,"C")/(COUNTIF(G9:G21,"C")+COUNTIF(G9:G21,"NC")),0)
A29: Non-conformités bloquantes | F29: =COUNTIFS(G9:G21,"NC",H9:H21,"Bloquant")
A30: Non-conformités gênantes | F30: =COUNTIFS(G9:G21,"NC",H9:H21,"Gênant")
A31: Non-conformités mineures | F31: =COUNTIFS(G9:G21,"NC",H9:H21,"Mineur")
A33: Top 3 des actions prioritaires
A34: 1.
A35: 2.
A36: 3.
A38: Mon engagement pour demain 9 h

Sheet 2. Mentions légales
A1: Auditeur / auditrice
A2: Date de l'audit
A3: URL de la page auditée
A4: Intitulé de la page | D4: Page « Mentions légales »
A5: Navigateur et version
A6: Outils utilisés
A8: N | B8: Easy Check | C8: WCAG 2.2 | D8: RGAA 4.1.2 | E8: Méthode de test | F8: Ce qu'il faut vérifier | G8: Verdict | H8: Sévérité | I8: Constat | J8: Correctif suggéré | K8: Preuve (URL, sélecteur, capture)
A9: 1 | B9: Alternatives textuelles des images | C9: 1.1.1 | D9: 1.1, 1.2, 1.3, 1.6, 1.7, 1.8, 1.9 | E9: Bookmarklet « Check images », ou clic droit Inspecter sur chaque image. | F9: Alt présent. Alt vide pour les décoratives. Alt explicite (action attendue) pour les images-liens. Description longue pour les graphiques et schémas complexes.
A10: 2 | B10: Titre de page | C10: 2.4.2 | D10: 8.5, 8.6 | E10: Survoler l'onglet du navigateur, lire la balise <title>. | F10: Titre présent, unique par page, information prioritaire placée en premier (front-loading).
A11: 3 | B11: Titres et hiérarchie | C11: 1.3.1, 2.4.6 | D11: 9.1 | E11: Extension HeadingsMap ou bookmarklet « Check headings ». | F11: Un seul <h1> par page. Niveaux emboîtés sans saut (H1 vers H2 vers H3). Titres balisés <h1> à <h6>, pas seulement stylés en CSS.
A12: 4 | B12: Contraste des couleurs | C12: 1.4.3, 1.4.11 | D12: 3.2, 3.3 | E12: Pipette DevTools, WebAIM Contrast Checker, Colour Contrast Analyser (CCA). | F12: Texte normal : ratio >= 4,5:1. Texte large (18 pt ou 14 pt gras) : ratio >= 3:1. Composants graphiques porteurs d'information : >= 3:1.
A13: 5 | B13: Lien d'évitement | C13: 2.4.1 | D13: 12.7 | E13: Charger la page, appuyer une fois sur Tab. | F13: 1er élément focus = lien « Aller au contenu ». Visible au focus même s'il est masqué par défaut. Ancre valide (#contenu, #main).
A14: 6 | B14: Focus et navigation clavier | C14: 2.4.7, 2.1.1, 2.1.2, 2.4.3 | D14: 10.7, 12.13, 12.14, 10.3 | E14: Cacher la souris. Parcours complet au clavier uniquement (Tab, Maj+Tab, Entrée, Espace, flèches). | F14: Focus visible sur tous les éléments interactifs. Ordre de tabulation logique. Pas de piège clavier. État (coché, développé, sélectionné) annoncé.
A15: 7 | B15: Langue de la page | C15: 3.1.1, 3.1.2 | D15: 8.3, 8.4 | E15: Clic droit « Afficher le code source », chercher <html lang="…">. | F15: Attribut lang présent avec code ISO 639 (fr, en, de…). Passages dans une autre langue balisés <span lang="…">.
A16: 8 | B16: Zoom à 200 % | C16: 1.4.4, 1.4.10 | D16: 10.4, 10.11 | E16: Ctrl + (Cmd + sur Mac) jusqu'à 200 %, parcourir la page complète. | F16: Aucun texte coupé ni superposé. Pas de défilement horizontal forcé. Menus, boutons et formulaires restent utilisables.
A17: 9 | B17: Sous-titres vidéo | C17: 1.2.2 | D17: 4.3, 4.4 | E17: Lancer la vidéo, couper le son, activer les sous-titres (bouton CC). | F17: Sous-titres synchronisés présents. Paroles + informations sonores importantes ((rires), (sonnerie)). Qualité éditoriale (pas auto-générés non relus).
A18: 10 | B18: Transcriptions audio et vidéo | C18: 1.2.1 | D18: 4.1, 4.2 | E18: Chercher un lien « Transcription » ou « Lire le texte » visible près du média. | F18: Transcription accessible à un clic. Complète (paroles + bruits utiles). Navigable (titres, paragraphes).
A19: 11 | B19: Audiodescription | C19: 1.2.3, 1.2.5 | D19: 4.5, 4.6 | E19: Vérifier la présence d'une piste audiodécrite (bouton AD). | F19: AD disponible pour les vidéos informatives à contenu visuel essentiel. Intercalée dans les silences, sans couvrir les dialogues.
A20: 12 | B20: Étiquettes de formulaire | C20: 3.3.2, 1.3.1, 2.5.3 | D20: 11.1, 11.2, 11.3 | E20: Cliquer sur le libellé (le focus doit sauter dans le champ). Tester au lecteur d'écran. | F20: Étiquette visible et persistante. Association <label for="…"> ou aria-labelledby. Placeholder = exemple, jamais étiquette unique. Fieldset/legend pour les groupes (radios, cases).
A21: 13 | B21: Champs obligatoires et erreurs | C21: 3.3.2, 3.3.1, 3.3.3 | D21: 11.10, 11.11 | E21: Soumettre un formulaire incomplet. Écouter l'annonce par le lecteur d'écran. | F21: Obligatoires indiqués textuellement et par astérisque. Légende « * champ obligatoire » présente. Messages d'erreur qui identifient le champ par son libellé.
A24: Synthèse de la page
A25: Conforme (C) | F25: =COUNTIF(G9:G21,"C")
A26: Non conforme (NC) | F26: =COUNTIF(G9:G21,"NC")
A27: Non applicable (NA) | F27: =COUNTIF(G9:G21,"NA")
A28: Taux de conformité Easy Checks | F28: =IFERROR(COUNTIF(G9:G21,"C")/(COUNTIF(G9:G21,"C")+COUNTIF(G9:G21,"NC")),0)
A29: Non-conformités bloquantes | F29: =COUNTIFS(G9:G21,"NC",H9:H21,"Bloquant")
A30: Non-conformités gênantes | F30: =COUNTIFS(G9:G21,"NC",H9:H21,"Gênant")
A31: Non-conformités mineures | F31: =COUNTIFS(G9:G21,"NC",H9:H21,"Mineur")
A33: Top 3 des actions prioritaires
A34: 1.
A35: 2.
A36: 3.
A38: Mon engagement pour demain 9 h

Sheet 3. Déclaration a11y
A1: Auditeur / auditrice
A2: Date de l'audit
A3: URL de la page auditée
A4: Intitulé de la page | D4: Déclaration d'accessibilité
A5: Navigateur et version
A6: Outils utilisés
A8: N | B8: Easy Check | C8: WCAG 2.2 | D8: RGAA 4.1.2 | E8: Méthode de test | F8: Ce qu'il faut vérifier | G8: Verdict | H8: Sévérité | I8: Constat | J8: Correctif suggéré | K8: Preuve (URL, sélecteur, capture)
A9: 1 | B9: Alternatives textuelles des images | C9: 1.1.1 | D9: 1.1, 1.2, 1.3, 1.6, 1.7, 1.8, 1.9 | E9: Bookmarklet « Check images », ou clic droit Inspecter sur chaque image. | F9: Alt présent. Alt vide pour les décoratives. Alt explicite (action attendue) pour les images-liens. Description longue pour les graphiques et schémas complexes.
A10: 2 | B10: Titre de page | C10: 2.4.2 | D10: 8.5, 8.6 | E10: Survoler l'onglet du navigateur, lire la balise <title>. | F10: Titre présent, unique par page, information prioritaire placée en premier (front-loading).
A11: 3 | B11: Titres et hiérarchie | C11: 1.3.1, 2.4.6 | D11: 9.1 | E11: Extension HeadingsMap ou bookmarklet « Check headings ». | F11: Un seul <h1> par page. Niveaux emboîtés sans saut (H1 vers H2 vers H3). Titres balisés <h1> à <h6>, pas seulement stylés en CSS.
A12: 4 | B12: Contraste des couleurs | C12: 1.4.3, 1.4.11 | D12: 3.2, 3.3 | E12: Pipette DevTools, WebAIM Contrast Checker, Colour Contrast Analyser (CCA). | F12: Texte normal : ratio >= 4,5:1. Texte large (18 pt ou 14 pt gras) : ratio >= 3:1. Composants graphiques porteurs d'information : >= 3:1.
A13: 5 | B13: Lien d'évitement | C13: 2.4.1 | D13: 12.7 | E13: Charger la page, appuyer une fois sur Tab. | F13: 1er élément focus = lien « Aller au contenu ». Visible au focus même s'il est masqué par défaut. Ancre valide (#contenu, #main).
A14: 6 | B14: Focus et navigation clavier | C14: 2.4.7, 2.1.1, 2.1.2, 2.4.3 | D14: 10.7, 12.13, 12.14, 10.3 | E14: Cacher la souris. Parcours complet au clavier uniquement (Tab, Maj+Tab, Entrée, Espace, flèches). | F14: Focus visible sur tous les éléments interactifs. Ordre de tabulation logique. Pas de piège clavier. État (coché, développé, sélectionné) annoncé.
A15: 7 | B15: Langue de la page | C15: 3.1.1, 3.1.2 | D15: 8.3, 8.4 | E15: Clic droit « Afficher le code source », chercher <html lang="…">. | F15: Attribut lang présent avec code ISO 639 (fr, en, de…). Passages dans une autre langue balisés <span lang="…">.
A16: 8 | B16: Zoom à 200 % | C16: 1.4.4, 1.4.10 | D16: 10.4, 10.11 | E16: Ctrl + (Cmd + sur Mac) jusqu'à 200 %, parcourir la page complète. | F16: Aucun texte coupé ni superposé. Pas de défilement horizontal forcé. Menus, boutons et formulaires restent utilisables.
A17: 9 | B17: Sous-titres vidéo | C17: 1.2.2 | D17: 4.3, 4.4 | E17: Lancer la vidéo, couper le son, activer les sous-titres (bouton CC). | F17: Sous-titres synchronisés présents. Paroles + informations sonores importantes ((rires), (sonnerie)). Qualité éditoriale (pas auto-générés non relus).
A18: 10 | B18: Transcriptions audio et vidéo | C18: 1.2.1 | D18: 4.1, 4.2 | E18: Chercher un lien « Transcription » ou « Lire le texte » visible près du média. | F18: Transcription accessible à un clic. Complète (paroles + bruits utiles). Navigable (titres, paragraphes).
A19: 11 | B19: Audiodescription | C19: 1.2.3, 1.2.5 | D19: 4.5, 4.6 | E19: Vérifier la présence d'une piste audiodécrite (bouton AD). | F19: AD disponible pour les vidéos informatives à contenu visuel essentiel. Intercalée dans les silences, sans couvrir les dialogues.
A20: 12 | B20: Étiquettes de formulaire | C20: 3.3.2, 1.3.1, 2.5.3 | D20: 11.1, 11.2, 11.3 | E20: Cliquer sur le libellé (le focus doit sauter dans le champ). Tester au lecteur d'écran. | F20: Étiquette visible et persistante. Association <label for="…"> ou aria-labelledby. Placeholder = exemple, jamais étiquette unique. Fieldset/legend pour les groupes (radios, cases).
A21: 13 | B21: Champs obligatoires et erreurs | C21: 3.3.2, 3.3.1, 3.3.3 | D21: 11.10, 11.11 | E21: Soumettre un formulaire incomplet. Écouter l'annonce par le lecteur d'écran. | F21: Obligatoires indiqués textuellement et par astérisque. Légende « * champ obligatoire » présente. Messages d'erreur qui identifient le champ par son libellé.
A24: Synthèse de la page
A25: Conforme (C) | F25: =COUNTIF(G9:G21,"C")
A26: Non conforme (NC) | F26: =COUNTIF(G9:G21,"NC")
A27: Non applicable (NA) | F27: =COUNTIF(G9:G21,"NA")
A28: Taux de conformité Easy Checks | F28: =IFERROR(COUNTIF(G9:G21,"C")/(COUNTIF(G9:G21,"C")+COUNTIF(G9:G21,"NC")),0)
A29: Non-conformités bloquantes | F29: =COUNTIFS(G9:G21,"NC",H9:H21,"Bloquant")
A30: Non-conformités gênantes | F30: =COUNTIFS(G9:G21,"NC",H9:H21,"Gênant")
A31: Non-conformités mineures | F31: =COUNTIFS(G9:G21,"NC",H9:H21,"Mineur")
A33: Top 3 des actions prioritaires
A34: 1.
A35: 2.
A36: 3.
A38: Mon engagement pour demain 9 h

Sheet 4. Plan du site
A1: Auditeur / auditrice
A2: Date de l'audit
A3: URL de la page auditée
A4: Intitulé de la page | D4: Page « Plan du site »
A5: Navigateur et version
A6: Outils utilisés
A8: N | B8: Easy Check | C8: WCAG 2.2 | D8: RGAA 4.1.2 | E8: Méthode de test | F8: Ce qu'il faut vérifier | G8: Verdict | H8: Sévérité | I8: Constat | J8: Correctif suggéré | K8: Preuve (URL, sélecteur, capture)
A9: 1 | B9: Alternatives textuelles des images | C9: 1.1.1 | D9: 1.1, 1.2, 1.3, 1.6, 1.7, 1.8, 1.9 | E9: Bookmarklet « Check images », ou clic droit Inspecter sur chaque image. | F9: Alt présent. Alt vide pour les décoratives. Alt explicite (action attendue) pour les images-liens. Description longue pour les graphiques et schémas complexes.
A10: 2 | B10: Titre de page | C10: 2.4.2 | D10: 8.5, 8.6 | E10: Survoler l'onglet du navigateur, lire la balise <title>. | F10: Titre présent, unique par page, information prioritaire placée en premier (front-loading).
A11: 3 | B11: Titres et hiérarchie | C11: 1.3.1, 2.4.6 | D11: 9.1 | E11: Extension HeadingsMap ou bookmarklet « Check headings ». | F11: Un seul <h1> par page. Niveaux emboîtés sans saut (H1 vers H2 vers H3). Titres balisés <h1> à <h6>, pas seulement stylés en CSS.
A12: 4 | B12: Contraste des couleurs | C12: 1.4.3, 1.4.11 | D12: 3.2, 3.3 | E12: Pipette DevTools, WebAIM Contrast Checker, Colour Contrast Analyser (CCA). | F12: Texte normal : ratio >= 4,5:1. Texte large (18 pt ou 14 pt gras) : ratio >= 3:1. Composants graphiques porteurs d'information : >= 3:1.
A13: 5 | B13: Lien d'évitement | C13: 2.4.1 | D13: 12.7 | E13: Charger la page, appuyer une fois sur Tab. | F13: 1er élément focus = lien « Aller au contenu ». Visible au focus même s'il est masqué par défaut. Ancre valide (#contenu, #main).
A14: 6 | B14: Focus et navigation clavier | C14: 2.4.7, 2.1.1, 2.1.2, 2.4.3 | D14: 10.7, 12.13, 12.14, 10.3 | E14: Cacher la souris. Parcours complet au clavier uniquement (Tab, Maj+Tab, Entrée, Espace, flèches). | F14: Focus visible sur tous les éléments interactifs. Ordre de tabulation logique. Pas de piège clavier. État (coché, développé, sélectionné) annoncé.
A15: 7 | B15: Langue de la page | C15: 3.1.1, 3.1.2 | D15: 8.3, 8.4 | E15: Clic droit « Afficher le code source », chercher <html lang="…">. | F15: Attribut lang présent avec code ISO 639 (fr, en, de…). Passages dans une autre langue balisés <span lang="…">.
A16: 8 | B16: Zoom à 200 % | C16: 1.4.4, 1.4.10 | D16: 10.4, 10.11 | E16: Ctrl + (Cmd + sur Mac) jusqu'à 200 %, parcourir la page complète. | F16: Aucun texte coupé ni superposé. Pas de défilement horizontal forcé. Menus, boutons et formulaires restent utilisables.
A17: 9 | B17: Sous-titres vidéo | C17: 1.2.2 | D17: 4.3, 4.4 | E17: Lancer la vidéo, couper le son, activer les sous-titres (bouton CC). | F17: Sous-titres synchronisés présents. Paroles + informations sonores importantes ((rires), (sonnerie)). Qualité éditoriale (pas auto-générés non relus).
A18: 10 | B18: Transcriptions audio et vidéo | C18: 1.2.1 | D18: 4.1, 4.2 | E18: Chercher un lien « Transcription » ou « Lire le texte » visible près du média. | F18: Transcription accessible à un clic. Complète (paroles + bruits utiles). Navigable (titres, paragraphes).
A19: 11 | B19: Audiodescription | C19: 1.2.3, 1.2.5 | D19: 4.5, 4.6 | E19: Vérifier la présence d'une piste audiodécrite (bouton AD). | F19: AD disponible pour les vidéos informatives à contenu visuel essentiel. Intercalée dans les silences, sans couvrir les dialogues.
A20: 12 | B20: Étiquettes de formulaire | C20: 3.3.2, 1.3.1, 2.5.3 | D20: 11.1, 11.2, 11.3 | E20: Cliquer sur le libellé (le focus doit sauter dans le champ). Tester au lecteur d'écran. | F20: Étiquette visible et persistante. Association <label for="…"> ou aria-labelledby. Placeholder = exemple, jamais étiquette unique. Fieldset/legend pour les groupes (radios, cases).
A21: 13 | B21: Champs obligatoires et erreurs | C21: 3.3.2, 3.3.1, 3.3.3 | D21: 11.10, 11.11 | E21: Soumettre un formulaire incomplet. Écouter l'annonce par le lecteur d'écran. | F21: Obligatoires indiqués textuellement et par astérisque. Légende « * champ obligatoire » présente. Messages d'erreur qui identifient le champ par son libellé.
A24: Synthèse de la page
A25: Conforme (C) | F25: =COUNTIF(G9:G21,"C")
A26: Non conforme (NC) | F26: =COUNTIF(G9:G21,"NC")
A27: Non applicable (NA) | F27: =COUNTIF(G9:G21,"NA")
A28: Taux de conformité Easy Checks | F28: =IFERROR(COUNTIF(G9:G21,"C")/(COUNTIF(G9:G21,"C")+COUNTIF(G9:G21,"NC")),0)
A29: Non-conformités bloquantes | F29: =COUNTIFS(G9:G21,"NC",H9:H21,"Bloquant")
A30: Non-conformités gênantes | F30: =COUNTIFS(G9:G21,"NC",H9:H21,"Gênant")
A31: Non-conformités mineures | F31: =COUNTIFS(G9:G21,"NC",H9:H21,"Mineur")
A33: Top 3 des actions prioritaires
A34: 1.
A35: 2.
A36: 3.
A38: Mon engagement pour demain 9 h

Sheet 5. Contact
A1: Auditeur / auditrice
A2: Date de l'audit
A3: URL de la page auditée
A4: Intitulé de la page | D4: Page « Contact »
A5: Navigateur et version
A6: Outils utilisés
A8: N | B8: Easy Check | C8: WCAG 2.2 | D8: RGAA 4.1.2 | E8: Méthode de test | F8: Ce qu'il faut vérifier | G8: Verdict | H8: Sévérité | I8: Constat | J8: Correctif suggéré | K8: Preuve (URL, sélecteur, capture)
A9: 1 | B9: Alternatives textuelles des images | C9: 1.1.1 | D9: 1.1, 1.2, 1.3, 1.6, 1.7, 1.8, 1.9 | E9: Bookmarklet « Check images », ou clic droit Inspecter sur chaque image. | F9: Alt présent. Alt vide pour les décoratives. Alt explicite (action attendue) pour les images-liens. Description longue pour les graphiques et schémas complexes.
A10: 2 | B10: Titre de page | C10: 2.4.2 | D10: 8.5, 8.6 | E10: Survoler l'onglet du navigateur, lire la balise <title>. | F10: Titre présent, unique par page, information prioritaire placée en premier (front-loading).
A11: 3 | B11: Titres et hiérarchie | C11: 1.3.1, 2.4.6 | D11: 9.1 | E11: Extension HeadingsMap ou bookmarklet « Check headings ». | F11: Un seul <h1> par page. Niveaux emboîtés sans saut (H1 vers H2 vers H3). Titres balisés <h1> à <h6>, pas seulement stylés en CSS.
A12: 4 | B12: Contraste des couleurs | C12: 1.4.3, 1.4.11 | D12: 3.2, 3.3 | E12: Pipette DevTools, WebAIM Contrast Checker, Colour Contrast Analyser (CCA). | F12: Texte normal : ratio >= 4,5:1. Texte large (18 pt ou 14 pt gras) : ratio >= 3:1. Composants graphiques porteurs d'information : >= 3:1.
A13: 5 | B13: Lien d'évitement | C13: 2.4.1 | D13: 12.7 | E13: Charger la page, appuyer une fois sur Tab. | F13: 1er élément focus = lien « Aller au contenu ». Visible au focus même s'il est masqué par défaut. Ancre valide (#contenu, #main).
A14: 6 | B14: Focus et navigation clavier | C14: 2.4.7, 2.1.1, 2.1.2, 2.4.3 | D14: 10.7, 12.13, 12.14, 10.3 | E14: Cacher la souris. Parcours complet au clavier uniquement (Tab, Maj+Tab, Entrée, Espace, flèches). | F14: Focus visible sur tous les éléments interactifs. Ordre de tabulation logique. Pas de piège clavier. État (coché, développé, sélectionné) annoncé.
A15: 7 | B15: Langue de la page | C15: 3.1.1, 3.1.2 | D15: 8.3, 8.4 | E15: Clic droit « Afficher le code source », chercher <html lang="…">. | F15: Attribut lang présent avec code ISO 639 (fr, en, de…). Passages dans une autre langue balisés <span lang="…">.
A16: 8 | B16: Zoom à 200 % | C16: 1.4.4, 1.4.10 | D16: 10.4, 10.11 | E16: Ctrl + (Cmd + sur Mac) jusqu'à 200 %, parcourir la page complète. | F16: Aucun texte coupé ni superposé. Pas de défilement horizontal forcé. Menus, boutons et formulaires restent utilisables.
A17: 9 | B17: Sous-titres vidéo | C17: 1.2.2 | D17: 4.3, 4.4 | E17: Lancer la vidéo, couper le son, activer les sous-titres (bouton CC). | F17: Sous-titres synchronisés présents. Paroles + informations sonores importantes ((rires), (sonnerie)). Qualité éditoriale (pas auto-générés non relus).
A18: 10 | B18: Transcriptions audio et vidéo | C18: 1.2.1 | D18: 4.1, 4.2 | E18: Chercher un lien « Transcription » ou « Lire le texte » visible près du média. | F18: Transcription accessible à un clic. Complète (paroles + bruits utiles). Navigable (titres, paragraphes).
A19: 11 | B19: Audiodescription | C19: 1.2.3, 1.2.5 | D19: 4.5, 4.6 | E19: Vérifier la présence d'une piste audiodécrite (bouton AD). | F19: AD disponible pour les vidéos informatives à contenu visuel essentiel. Intercalée dans les silences, sans couvrir les dialogues.
A20: 12 | B20: Étiquettes de formulaire | C20: 3.3.2, 1.3.1, 2.5.3 | D20: 11.1, 11.2, 11.3 | E20: Cliquer sur le libellé (le focus doit sauter dans le champ). Tester au lecteur d'écran. | F20: Étiquette visible et persistante. Association <label for="…"> ou aria-labelledby. Placeholder = exemple, jamais étiquette unique. Fieldset/legend pour les groupes (radios, cases).
A21: 13 | B21: Champs obligatoires et erreurs | C21: 3.3.2, 3.3.1, 3.3.3 | D21: 11.10, 11.11 | E21: Soumettre un formulaire incomplet. Écouter l'annonce par le lecteur d'écran. | F21: Obligatoires indiqués textuellement et par astérisque. Légende « * champ obligatoire » présente. Messages d'erreur qui identifient le champ par son libellé.
A24: Synthèse de la page
A25: Conforme (C) | F25: =COUNTIF(G9:G21,"C")
A26: Non conforme (NC) | F26: =COUNTIF(G9:G21,"NC")
A27: Non applicable (NA) | F27: =COUNTIF(G9:G21,"NA")
A28: Taux de conformité Easy Checks | F28: =IFERROR(COUNTIF(G9:G21,"C")/(COUNTIF(G9:G21,"C")+COUNTIF(G9:G21,"NC")),0)
A29: Non-conformités bloquantes | F29: =COUNTIFS(G9:G21,"NC",H9:H21,"Bloquant")
A30: Non-conformités gênantes | F30: =COUNTIFS(G9:G21,"NC",H9:H21,"Gênant")
A31: Non-conformités mineures | F31: =COUNTIFS(G9:G21,"NC",H9:H21,"Mineur")
A33: Top 3 des actions prioritaires
A34: 1.
A35: 2.
A36: 3.
A38: Mon engagement pour demain 9 h

Sheet 6. Aide
A1: Auditeur / auditrice
A2: Date de l'audit
A3: URL de la page auditée
A4: Intitulé de la page | D4: Page « Aide » / FAQ
A5: Navigateur et version
A6: Outils utilisés
A8: N | B8: Easy Check | C8: WCAG 2.2 | D8: RGAA 4.1.2 | E8: Méthode de test | F8: Ce qu'il faut vérifier | G8: Verdict | H8: Sévérité | I8: Constat | J8: Correctif suggéré | K8: Preuve (URL, sélecteur, capture)
A9: 1 | B9: Alternatives textuelles des images | C9: 1.1.1 | D9: 1.1, 1.2, 1.3, 1.6, 1.7, 1.8, 1.9 | E9: Bookmarklet « Check images », ou clic droit Inspecter sur chaque image. | F9: Alt présent. Alt vide pour les décoratives. Alt explicite (action attendue) pour les images-liens. Description longue pour les graphiques et schémas complexes.
A10: 2 | B10: Titre de page | C10: 2.4.2 | D10: 8.5, 8.6 | E10: Survoler l'onglet du navigateur, lire la balise <title>. | F10: Titre présent, unique par page, information prioritaire placée en premier (front-loading).
A11: 3 | B11: Titres et hiérarchie | C11: 1.3.1, 2.4.6 | D11: 9.1 | E11: Extension HeadingsMap ou bookmarklet « Check headings ». | F11: Un seul <h1> par page. Niveaux emboîtés sans saut (H1 vers H2 vers H3). Titres balisés <h1> à <h6>, pas seulement stylés en CSS.
A12: 4 | B12: Contraste des couleurs | C12: 1.4.3, 1.4.11 | D12: 3.2, 3.3 | E12: Pipette DevTools, WebAIM Contrast Checker, Colour Contrast Analyser (CCA). | F12: Texte normal : ratio >= 4,5:1. Texte large (18 pt ou 14 pt gras) : ratio >= 3:1. Composants graphiques porteurs d'information : >= 3:1.
A13: 5 | B13: Lien d'évitement | C13: 2.4.1 | D13: 12.7 | E13: Charger la page, appuyer une fois sur Tab. | F13: 1er élément focus = lien « Aller au contenu ». Visible au focus même s'il est masqué par défaut. Ancre valide (#contenu, #main).
A14: 6 | B14: Focus et navigation clavier | C14: 2.4.7, 2.1.1, 2.1.2, 2.4.3 | D14: 10.7, 12.13, 12.14, 10.3 | E14: Cacher la souris. Parcours complet au clavier uniquement (Tab, Maj+Tab, Entrée, Espace, flèches). | F14: Focus visible sur tous les éléments interactifs. Ordre de tabulation logique. Pas de piège clavier. État (coché, développé, sélectionné) annoncé.
A15: 7 | B15: Langue de la page | C15: 3.1.1, 3.1.2 | D15: 8.3, 8.4 | E15: Clic droit « Afficher le code source », chercher <html lang="…">. | F15: Attribut lang présent avec code ISO 639 (fr, en, de…). Passages dans une autre langue balisés <span lang="…">.
A16: 8 | B16: Zoom à 200 % | C16: 1.4.4, 1.4.10 | D16: 10.4, 10.11 | E16: Ctrl + (Cmd + sur Mac) jusqu'à 200 %, parcourir la page complète. | F16: Aucun texte coupé ni superposé. Pas de défilement horizontal forcé. Menus, boutons et formulaires restent utilisables.
A17: 9 | B17: Sous-titres vidéo | C17: 1.2.2 | D17: 4.3, 4.4 | E17: Lancer la vidéo, couper le son, activer les sous-titres (bouton CC). | F17: Sous-titres synchronisés présents. Paroles + informations sonores importantes ((rires), (sonnerie)). Qualité éditoriale (pas auto-générés non relus).
A18: 10 | B18: Transcriptions audio et vidéo | C18: 1.2.1 | D18: 4.1, 4.2 | E18: Chercher un lien « Transcription » ou « Lire le texte » visible près du média. | F18: Transcription accessible à un clic. Complète (paroles + bruits utiles). Navigable (titres, paragraphes).
A19: 11 | B19: Audiodescription | C19: 1.2.3, 1.2.5 | D19: 4.5, 4.6 | E19: Vérifier la présence d'une piste audiodécrite (bouton AD). | F19: AD disponible pour les vidéos informatives à contenu visuel essentiel. Intercalée dans les silences, sans couvrir les dialogues.
A20: 12 | B20: Étiquettes de formulaire | C20: 3.3.2, 1.3.1, 2.5.3 | D20: 11.1, 11.2, 11.3 | E20: Cliquer sur le libellé (le focus doit sauter dans le champ). Tester au lecteur d'écran. | F20: Étiquette visible et persistante. Association <label for="…"> ou aria-labelledby. Placeholder = exemple, jamais étiquette unique. Fieldset/legend pour les groupes (radios, cases).
A21: 13 | B21: Champs obligatoires et erreurs | C21: 3.3.2, 3.3.1, 3.3.3 | D21: 11.10, 11.11 | E21: Soumettre un formulaire incomplet. Écouter l'annonce par le lecteur d'écran. | F21: Obligatoires indiqués textuellement et par astérisque. Légende « * champ obligatoire » présente. Messages d'erreur qui identifient le champ par son libellé.
A24: Synthèse de la page
A25: Conforme (C) | F25: =COUNTIF(G9:G21,"C")
A26: Non conforme (NC) | F26: =COUNTIF(G9:G21,"NC")
A27: Non applicable (NA) | F27: =COUNTIF(G9:G21,"NA")
A28: Taux de conformité Easy Checks | F28: =IFERROR(COUNTIF(G9:G21,"C")/(COUNTIF(G9:G21,"C")+COUNTIF(G9:G21,"NC")),0)
A29: Non-conformités bloquantes | F29: =COUNTIFS(G9:G21,"NC",H9:H21,"Bloquant")
A30: Non-conformités gênantes | F30: =COUNTIFS(G9:G21,"NC",H9:H21,"Gênant")
A31: Non-conformités mineures | F31: =COUNTIFS(G9:G21,"NC",H9:H21,"Mineur")
A33: Top 3 des actions prioritaires
A34: 1.
A35: 2.
A36: 3.
A38: Mon engagement pour demain 9 h

Sheet 7. Authentification
A1: Auditeur / auditrice
A2: Date de l'audit
A3: URL de la page auditée
A4: Intitulé de la page | D4: Page d'authentification / connexion
A5: Navigateur et version
A6: Outils utilisés
A8: N | B8: Easy Check | C8: WCAG 2.2 | D8: RGAA 4.1.2 | E8: Méthode de test | F8: Ce qu'il faut vérifier | G8: Verdict | H8: Sévérité | I8: Constat | J8: Correctif suggéré | K8: Preuve (URL, sélecteur, capture)
A9: 1 | B9: Alternatives textuelles des images | C9: 1.1.1 | D9: 1.1, 1.2, 1.3, 1.6, 1.7, 1.8, 1.9 | E9: Bookmarklet « Check images », ou clic droit Inspecter sur chaque image. | F9: Alt présent. Alt vide pour les décoratives. Alt explicite (action attendue) pour les images-liens. Description longue pour les graphiques et schémas complexes.
A10: 2 | B10: Titre de page | C10: 2.4.2 | D10: 8.5, 8.6 | E10: Survoler l'onglet du navigateur, lire la balise <title>. | F10: Titre présent, unique par page, information prioritaire placée en premier (front-loading).
A11: 3 | B11: Titres et hiérarchie | C11: 1.3.1, 2.4.6 | D11: 9.1 | E11: Extension HeadingsMap ou bookmarklet « Check headings ». | F11: Un seul <h1> par page. Niveaux emboîtés sans saut (H1 vers H2 vers H3). Titres balisés <h1> à <h6>, pas seulement stylés en CSS.
A12: 4 | B12: Contraste des couleurs | C12: 1.4.3, 1.4.11 | D12: 3.2, 3.3 | E12: Pipette DevTools, WebAIM Contrast Checker, Colour Contrast Analyser (CCA). | F12: Texte normal : ratio >= 4,5:1. Texte large (18 pt ou 14 pt gras) : ratio >= 3:1. Composants graphiques porteurs d'information : >= 3:1.
A13: 5 | B13: Lien d'évitement | C13: 2.4.1 | D13: 12.7 | E13: Charger la page, appuyer une fois sur Tab. | F13: 1er élément focus = lien « Aller au contenu ». Visible au focus même s'il est masqué par défaut. Ancre valide (#contenu, #main).
A14: 6 | B14: Focus et navigation clavier | C14: 2.4.7, 2.1.1, 2.1.2, 2.4.3 | D14: 10.7, 12.13, 12.14, 10.3 | E14: Cacher la souris. Parcours complet au clavier uniquement (Tab, Maj+Tab, Entrée, Espace, flèches). | F14: Focus visible sur tous les éléments interactifs. Ordre de tabulation logique. Pas de piège clavier. État (coché, développé, sélectionné) annoncé.
A15: 7 | B15: Langue de la page | C15: 3.1.1, 3.1.2 | D15: 8.3, 8.4 | E15: Clic droit « Afficher le code source », chercher <html lang="…">. | F15: Attribut lang présent avec code ISO 639 (fr, en, de…). Passages dans une autre langue balisés <span lang="…">.
A16: 8 | B16: Zoom à 200 % | C16: 1.4.4, 1.4.10 | D16: 10.4, 10.11 | E16: Ctrl + (Cmd + sur Mac) jusqu'à 200 %, parcourir la page complète. | F16: Aucun texte coupé ni superposé. Pas de défilement horizontal forcé. Menus, boutons et formulaires restent utilisables.
A17: 9 | B17: Sous-titres vidéo | C17: 1.2.2 | D17: 4.3, 4.4 | E17: Lancer la vidéo, couper le son, activer les sous-titres (bouton CC). | F17: Sous-titres synchronisés présents. Paroles + informations sonores importantes ((rires), (sonnerie)). Qualité éditoriale (pas auto-générés non relus).
A18: 10 | B18: Transcriptions audio et vidéo | C18: 1.2.1 | D18: 4.1, 4.2 | E18: Chercher un lien « Transcription » ou « Lire le texte » visible près du média. | F18: Transcription accessible à un clic. Complète (paroles + bruits utiles). Navigable (titres, paragraphes).
A19: 11 | B19: Audiodescription | C19: 1.2.3, 1.2.5 | D19: 4.5, 4.6 | E19: Vérifier la présence d'une piste audiodécrite (bouton AD). | F19: AD disponible pour les vidéos informatives à contenu visuel essentiel. Intercalée dans les silences, sans couvrir les dialogues.
A20: 12 | B20: Étiquettes de formulaire | C20: 3.3.2, 1.3.1, 2.5.3 | D20: 11.1, 11.2, 11.3 | E20: Cliquer sur le libellé (le focus doit sauter dans le champ). Tester au lecteur d'écran. | F20: Étiquette visible et persistante. Association <label for="…"> ou aria-labelledby. Placeholder = exemple, jamais étiquette unique. Fieldset/legend pour les groupes (radios, cases).
A21: 13 | B21: Champs obligatoires et erreurs | C21: 3.3.2, 3.3.1, 3.3.3 | D21: 11.10, 11.11 | E21: Soumettre un formulaire incomplet. Écouter l'annonce par le lecteur d'écran. | F21: Obligatoires indiqués textuellement et par astérisque. Légende « * champ obligatoire » présente. Messages d'erreur qui identifient le champ par son libellé.
A24: Synthèse de la page
A25: Conforme (C) | F25: =COUNTIF(G9:G21,"C")
A26: Non conforme (NC) | F26: =COUNTIF(G9:G21,"NC")
A27: Non applicable (NA) | F27: =COUNTIF(G9:G21,"NA")
A28: Taux de conformité Easy Checks | F28: =IFERROR(COUNTIF(G9:G21,"C")/(COUNTIF(G9:G21,"C")+COUNTIF(G9:G21,"NC")),0)
A29: Non-conformités bloquantes | F29: =COUNTIFS(G9:G21,"NC",H9:H21,"Bloquant")
A30: Non-conformités gênantes | F30: =COUNTIFS(G9:G21,"NC",H9:H21,"Gênant")
A31: Non-conformités mineures | F31: =COUNTIFS(G9:G21,"NC",H9:H21,"Mineur")
A33: Top 3 des actions prioritaires
A34: 1.
A35: 2.
A36: 3.
A38: Mon engagement pour demain 9 h

Sheet 8. Recherche
A1: Auditeur / auditrice
A2: Date de l'audit
A3: URL de la page auditée
A4: Intitulé de la page | D4: Page de résultats de recherche
A5: Navigateur et version
A6: Outils utilisés
A8: N | B8: Easy Check | C8: WCAG 2.2 | D8: RGAA 4.1.2 | E8: Méthode de test | F8: Ce qu'il faut vérifier | G8: Verdict | H8: Sévérité | I8: Constat | J8: Correctif suggéré | K8: Preuve (URL, sélecteur, capture)
A9: 1 | B9: Alternatives textuelles des images | C9: 1.1.1 | D9: 1.1, 1.2, 1.3, 1.6, 1.7, 1.8, 1.9 | E9: Bookmarklet « Check images », ou clic droit Inspecter sur chaque image. | F9: Alt présent. Alt vide pour les décoratives. Alt explicite (action attendue) pour les images-liens. Description longue pour les graphiques et schémas complexes.
A10: 2 | B10: Titre de page | C10: 2.4.2 | D10: 8.5, 8.6 | E10: Survoler l'onglet du navigateur, lire la balise <title>. | F10: Titre présent, unique par page, information prioritaire placée en premier (front-loading).
A11: 3 | B11: Titres et hiérarchie | C11: 1.3.1, 2.4.6 | D11: 9.1 | E11: Extension HeadingsMap ou bookmarklet « Check headings ». | F11: Un seul <h1> par page. Niveaux emboîtés sans saut (H1 vers H2 vers H3). Titres balisés <h1> à <h6>, pas seulement stylés en CSS.
A12: 4 | B12: Contraste des couleurs | C12: 1.4.3, 1.4.11 | D12: 3.2, 3.3 | E12: Pipette DevTools, WebAIM Contrast Checker, Colour Contrast Analyser (CCA). | F12: Texte normal : ratio >= 4,5:1. Texte large (18 pt ou 14 pt gras) : ratio >= 3:1. Composants graphiques porteurs d'information : >= 3:1.
A13: 5 | B13: Lien d'évitement | C13: 2.4.1 | D13: 12.7 | E13: Charger la page, appuyer une fois sur Tab. | F13: 1er élément focus = lien « Aller au contenu ». Visible au focus même s'il est masqué par défaut. Ancre valide (#contenu, #main).
A14: 6 | B14: Focus et navigation clavier | C14: 2.4.7, 2.1.1, 2.1.2, 2.4.3 | D14: 10.7, 12.13, 12.14, 10.3 | E14: Cacher la souris. Parcours complet au clavier uniquement (Tab, Maj+Tab, Entrée, Espace, flèches). | F14: Focus visible sur tous les éléments interactifs. Ordre de tabulation logique. Pas de piège clavier. État (coché, développé, sélectionné) annoncé.
A15: 7 | B15: Langue de la page | C15: 3.1.1, 3.1.2 | D15: 8.3, 8.4 | E15: Clic droit « Afficher le code source », chercher <html lang="…">. | F15: Attribut lang présent avec code ISO 639 (fr, en, de…). Passages dans une autre langue balisés <span lang="…">.
A16: 8 | B16: Zoom à 200 % | C16: 1.4.4, 1.4.10 | D16: 10.4, 10.11 | E16: Ctrl + (Cmd + sur Mac) jusqu'à 200 %, parcourir la page complète. | F16: Aucun texte coupé ni superposé. Pas de défilement horizontal forcé. Menus, boutons et formulaires restent utilisables.
A17: 9 | B17: Sous-titres vidéo | C17: 1.2.2 | D17: 4.3, 4.4 | E17: Lancer la vidéo, couper le son, activer les sous-titres (bouton CC). | F17: Sous-titres synchronisés présents. Paroles + informations sonores importantes ((rires), (sonnerie)). Qualité éditoriale (pas auto-générés non relus).
A18: 10 | B18: Transcriptions audio et vidéo | C18: 1.2.1 | D18: 4.1, 4.2 | E18: Chercher un lien « Transcription » ou « Lire le texte » visible près du média. | F18: Transcription accessible à un clic. Complète (paroles + bruits utiles). Navigable (titres, paragraphes).
A19: 11 | B19: Audiodescription | C19: 1.2.3, 1.2.5 | D19: 4.5, 4.6 | E19: Vérifier la présence d'une piste audiodécrite (bouton AD). | F19: AD disponible pour les vidéos informatives à contenu visuel essentiel. Intercalée dans les silences, sans couvrir les dialogues.
A20: 12 | B20: Étiquettes de formulaire | C20: 3.3.2, 1.3.1, 2.5.3 | D20: 11.1, 11.2, 11.3 | E20: Cliquer sur le libellé (le focus doit sauter dans le champ). Tester au lecteur d'écran. | F20: Étiquette visible et persistante. Association <label for="…"> ou aria-labelledby. Placeholder = exemple, jamais étiquette unique. Fieldset/legend pour les groupes (radios, cases).
A21: 13 | B21: Champs obligatoires et erreurs | C21: 3.3.2, 3.3.1, 3.3.3 | D21: 11.10, 11.11 | E21: Soumettre un formulaire incomplet. Écouter l'annonce par le lecteur d'écran. | F21: Obligatoires indiqués textuellement et par astérisque. Légende « * champ obligatoire » présente. Messages d'erreur qui identifient le champ par son libellé.
A24: Synthèse de la page
A25: Conforme (C) | F25: =COUNTIF(G9:G21,"C")
A26: Non conforme (NC) | F26: =COUNTIF(G9:G21,"NC")
A27: Non applicable (NA) | F27: =COUNTIF(G9:G21,"NA")
A28: Taux de conformité Easy Checks | F28: =IFERROR(COUNTIF(G9:G21,"C")/(COUNTIF(G9:G21,"C")+COUNTIF(G9:G21,"NC")),0)
A29: Non-conformités bloquantes | F29: =COUNTIFS(G9:G21,"NC",H9:H21,"Bloquant")
A30: Non-conformités gênantes | F30: =COUNTIFS(G9:G21,"NC",H9:H21,"Gênant")
A31: Non-conformités mineures | F31: =COUNTIFS(G9:G21,"NC",H9:H21,"Mineur")
A33: Top 3 des actions prioritaires
A34: 1.
A35: 2.
A36: 3.
A38: Mon engagement pour demain 9 h

Sheet 9. Document
A1: Auditeur / auditrice
A2: Date de l'audit
A3: URL de la page auditée
A4: Intitulé de la page | D4: Document téléchargeable (PDF, DOCX, ODT)
A5: Navigateur et version
A6: Outils utilisés
A7: Attention : les 13 Easy Checks web ne couvrent que partiellement les documents. Pour un audit formel des PDF / DOCX / ODT, utiliser PAC 2024 (outil gratuit), Acrobat Pro ou Axes4.
A8: N | B8: Easy Check | C8: WCAG 2.2 | D8: RGAA 4.1.2 | E8: Méthode de test | F8: Ce qu'il faut vérifier | G8: Verdict | H8: Sévérité | I8: Constat | J8: Correctif suggéré | K8: Preuve (URL, sélecteur, capture)
A9: 1 | B9: Alternatives textuelles des images | C9: 1.1.1 | D9: 1.1, 1.2, 1.3, 1.6, 1.7, 1.8, 1.9 | E9: Bookmarklet « Check images », ou clic droit Inspecter sur chaque image. | F9: Alt présent. Alt vide pour les décoratives. Alt explicite (action attendue) pour les images-liens. Description longue pour les graphiques et schémas complexes.
A10: 2 | B10: Titre de page | C10: 2.4.2 | D10: 8.5, 8.6 | E10: Survoler l'onglet du navigateur, lire la balise <title>. | F10: Titre présent, unique par page, information prioritaire placée en premier (front-loading).
A11: 3 | B11: Titres et hiérarchie | C11: 1.3.1, 2.4.6 | D11: 9.1 | E11: Extension HeadingsMap ou bookmarklet « Check headings ». | F11: Un seul <h1> par page. Niveaux emboîtés sans saut (H1 vers H2 vers H3). Titres balisés <h1> à <h6>, pas seulement stylés en CSS.
A12: 4 | B12: Contraste des couleurs | C12: 1.4.3, 1.4.11 | D12: 3.2, 3.3 | E12: Pipette DevTools, WebAIM Contrast Checker, Colour Contrast Analyser (CCA). | F12: Texte normal : ratio >= 4,5:1. Texte large (18 pt ou 14 pt gras) : ratio >= 3:1. Composants graphiques porteurs d'information : >= 3:1.
A13: 5 | B13: Lien d'évitement | C13: 2.4.1 | D13: 12.7 | E13: Charger la page, appuyer une fois sur Tab. | F13: 1er élément focus = lien « Aller au contenu ». Visible au focus même s'il est masqué par défaut. Ancre valide (#contenu, #main).
A14: 6 | B14: Focus et navigation clavier | C14: 2.4.7, 2.1.1, 2.1.2, 2.4.3 | D14: 10.7, 12.13, 12.14, 10.3 | E14: Cacher la souris. Parcours complet au clavier uniquement (Tab, Maj+Tab, Entrée, Espace, flèches). | F14: Focus visible sur tous les éléments interactifs. Ordre de tabulation logique. Pas de piège clavier. État (coché, développé, sélectionné) annoncé.
A15: 7 | B15: Langue de la page | C15: 3.1.1, 3.1.2 | D15: 8.3, 8.4 | E15: Clic droit « Afficher le code source », chercher <html lang="…">. | F15: Attribut lang présent avec code ISO 639 (fr, en, de…). Passages dans une autre langue balisés <span lang="…">.
A16: 8 | B16: Zoom à 200 % | C16: 1.4.4, 1.4.10 | D16: 10.4, 10.11 | E16: Ctrl + (Cmd + sur Mac) jusqu'à 200 %, parcourir la page complète. | F16: Aucun texte coupé ni superposé. Pas de défilement horizontal forcé. Menus, boutons et formulaires restent utilisables.
A17: 9 | B17: Sous-titres vidéo | C17: 1.2.2 | D17: 4.3, 4.4 | E17: Lancer la vidéo, couper le son, activer les sous-titres (bouton CC). | F17: Sous-titres synchronisés présents. Paroles + informations sonores importantes ((rires), (sonnerie)). Qualité éditoriale (pas auto-générés non relus).
A18: 10 | B18: Transcriptions audio et vidéo | C18: 1.2.1 | D18: 4.1, 4.2 | E18: Chercher un lien « Transcription » ou « Lire le texte » visible près du média. | F18: Transcription accessible à un clic. Complète (paroles + bruits utiles). Navigable (titres, paragraphes).
A19: 11 | B19: Audiodescription | C19: 1.2.3, 1.2.5 | D19: 4.5, 4.6 | E19: Vérifier la présence d'une piste audiodécrite (bouton AD). | F19: AD disponible pour les vidéos informatives à contenu visuel essentiel. Intercalée dans les silences, sans couvrir les dialogues.
A20: 12 | B20: Étiquettes de formulaire | C20: 3.3.2, 1.3.1, 2.5.3 | D20: 11.1, 11.2, 11.3 | E20: Cliquer sur le libellé (le focus doit sauter dans le champ). Tester au lecteur d'écran. | F20: Étiquette visible et persistante. Association <label for="…"> ou aria-labelledby. Placeholder = exemple, jamais étiquette unique. Fieldset/legend pour les groupes (radios, cases).
A21: 13 | B21: Champs obligatoires et erreurs | C21: 3.3.2, 3.3.1, 3.3.3 | D21: 11.10, 11.11 | E21: Soumettre un formulaire incomplet. Écouter l'annonce par le lecteur d'écran. | F21: Obligatoires indiqués textuellement et par astérisque. Légende « * champ obligatoire » présente. Messages d'erreur qui identifient le champ par son libellé.
A24: Synthèse de la page
A25: Conforme (C) | F25: =COUNTIF(G9:G21,"C")
A26: Non conforme (NC) | F26: =COUNTIF(G9:G21,"NC")
A27: Non applicable (NA) | F27: =COUNTIF(G9:G21,"NA")
A28: Taux de conformité Easy Checks | F28: =IFERROR(COUNTIF(G9:G21,"C")/(COUNTIF(G9:G21,"C")+COUNTIF(G9:G21,"NC")),0)
A29: Non-conformités bloquantes | F29: =COUNTIFS(G9:G21,"NC",H9:H21,"Bloquant")
A30: Non-conformités gênantes | F30: =COUNTIFS(G9:G21,"NC",H9:H21,"Gênant")
A31: Non-conformités mineures | F31: =COUNTIFS(G9:G21,"NC",H9:H21,"Mineur")
A33: Top 3 des actions prioritaires
A34: 1.
A35: 2.
A36: 3.
A38: Mon engagement pour demain 9 h

Sheet 10. Article
A1: Auditeur / auditrice
A2: Date de l'audit
A3: URL de la page auditée
A4: Intitulé de la page | D4: Page type : article, actualité ou contenu rédactionnel
A5: Navigateur et version
A6: Outils utilisés
A8: N | B8: Easy Check | C8: WCAG 2.2 | D8: RGAA 4.1.2 | E8: Méthode de test | F8: Ce qu'il faut vérifier | G8: Verdict | H8: Sévérité | I8: Constat | J8: Correctif suggéré | K8: Preuve (URL, sélecteur, capture)
A9: 1 | B9: Alternatives textuelles des images | C9: 1.1.1 | D9: 1.1, 1.2, 1.3, 1.6, 1.7, 1.8, 1.9 | E9: Bookmarklet « Check images », ou clic droit Inspecter sur chaque image. | F9: Alt présent. Alt vide pour les décoratives. Alt explicite (action attendue) pour les images-liens. Description longue pour les graphiques et schémas complexes.
A10: 2 | B10: Titre de page | C10: 2.4.2 | D10: 8.5, 8.6 | E10: Survoler l'onglet du navigateur, lire la balise <title>. | F10: Titre présent, unique par page, information prioritaire placée en premier (front-loading).
A11: 3 | B11: Titres et hiérarchie | C11: 1.3.1, 2.4.6 | D11: 9.1 | E11: Extension HeadingsMap ou bookmarklet « Check headings ». | F11: Un seul <h1> par page. Niveaux emboîtés sans saut (H1 vers H2 vers H3). Titres balisés <h1> à <h6>, pas seulement stylés en CSS.
A12: 4 | B12: Contraste des couleurs | C12: 1.4.3, 1.4.11 | D12: 3.2, 3.3 | E12: Pipette DevTools, WebAIM Contrast Checker, Colour Contrast Analyser (CCA). | F12: Texte normal : ratio >= 4,5:1. Texte large (18 pt ou 14 pt gras) : ratio >= 3:1. Composants graphiques porteurs d'information : >= 3:1.
A13: 5 | B13: Lien d'évitement | C13: 2.4.1 | D13: 12.7 | E13: Charger la page, appuyer une fois sur Tab. | F13: 1er élément focus = lien « Aller au contenu ». Visible au focus même s'il est masqué par défaut. Ancre valide (#contenu, #main).
A14: 6 | B14: Focus et navigation clavier | C14: 2.4.7, 2.1.1, 2.1.2, 2.4.3 | D14: 10.7, 12.13, 12.14, 10.3 | E14: Cacher la souris. Parcours complet au clavier uniquement (Tab, Maj+Tab, Entrée, Espace, flèches). | F14: Focus visible sur tous les éléments interactifs. Ordre de tabulation logique. Pas de piège clavier. État (coché, développé, sélectionné) annoncé.
A15: 7 | B15: Langue de la page | C15: 3.1.1, 3.1.2 | D15: 8.3, 8.4 | E15: Clic droit « Afficher le code source », chercher <html lang="…">. | F15: Attribut lang présent avec code ISO 639 (fr, en, de…). Passages dans une autre langue balisés <span lang="…">.
A16: 8 | B16: Zoom à 200 % | C16: 1.4.4, 1.4.10 | D16: 10.4, 10.11 | E16: Ctrl + (Cmd + sur Mac) jusqu'à 200 %, parcourir la page complète. | F16: Aucun texte coupé ni superposé. Pas de défilement horizontal forcé. Menus, boutons et formulaires restent utilisables.
A17: 9 | B17: Sous-titres vidéo | C17: 1.2.2 | D17: 4.3, 4.4 | E17: Lancer la vidéo, couper le son, activer les sous-titres (bouton CC). | F17: Sous-titres synchronisés présents. Paroles + informations sonores importantes ((rires), (sonnerie)). Qualité éditoriale (pas auto-générés non relus).
A18: 10 | B18: Transcriptions audio et vidéo | C18: 1.2.1 | D18: 4.1, 4.2 | E18: Chercher un lien « Transcription » ou « Lire le texte » visible près du média. | F18: Transcription accessible à un clic. Complète (paroles + bruits utiles). Navigable (titres, paragraphes).
A19: 11 | B19: Audiodescription | C19: 1.2.3, 1.2.5 | D19: 4.5, 4.6 | E19: Vérifier la présence d'une piste audiodécrite (bouton AD). | F19: AD disponible pour les vidéos informatives à contenu visuel essentiel. Intercalée dans les silences, sans couvrir les dialogues.
A20: 12 | B20: Étiquettes de formulaire | C20: 3.3.2, 1.3.1, 2.5.3 | D20: 11.1, 11.2, 11.3 | E20: Cliquer sur le libellé (le focus doit sauter dans le champ). Tester au lecteur d'écran. | F20: Étiquette visible et persistante. Association <label for="…"> ou aria-labelledby. Placeholder = exemple, jamais étiquette unique. Fieldset/legend pour les groupes (radios, cases).
A21: 13 | B21: Champs obligatoires et erreurs | C21: 3.3.2, 3.3.1, 3.3.3 | D21: 11.10, 11.11 | E21: Soumettre un formulaire incomplet. Écouter l'annonce par le lecteur d'écran. | F21: Obligatoires indiqués textuellement et par astérisque. Légende « * champ obligatoire » présente. Messages d'erreur qui identifient le champ par son libellé.
A24: Synthèse de la page
A25: Conforme (C) | F25: =COUNTIF(G9:G21,"C")
A26: Non conforme (NC) | F26: =COUNTIF(G9:G21,"NC")
A27: Non applicable (NA) | F27: =COUNTIF(G9:G21,"NA")
A28: Taux de conformité Easy Checks | F28: =IFERROR(COUNTIF(G9:G21,"C")/(COUNTIF(G9:G21,"C")+COUNTIF(G9:G21,"NC")),0)
A29: Non-conformités bloquantes | F29: =COUNTIFS(G9:G21,"NC",H9:H21,"Bloquant")
A30: Non-conformités gênantes | F30: =COUNTIFS(G9:G21,"NC",H9:H21,"Gênant")
A31: Non-conformités mineures | F31: =COUNTIFS(G9:G21,"NC",H9:H21,"Mineur")
A33: Top 3 des actions prioritaires
A34: 1.
A35: 2.
A36: 3.
A38: Mon engagement pour demain 9 h

Sheet 11. Formulaire
A1: Auditeur / auditrice
A2: Date de l'audit
A3: URL de la page auditée
A4: Intitulé de la page | D4: Page type : formulaire de démarche ou saisie multi-étape
A5: Navigateur et version
A6: Outils utilisés
A8: N | B8: Easy Check | C8: WCAG 2.2 | D8: RGAA 4.1.2 | E8: Méthode de test | F8: Ce qu'il faut vérifier | G8: Verdict | H8: Sévérité | I8: Constat | J8: Correctif suggéré | K8: Preuve (URL, sélecteur, capture)
A9: 1 | B9: Alternatives textuelles des images | C9: 1.1.1 | D9: 1.1, 1.2, 1.3, 1.6, 1.7, 1.8, 1.9 | E9: Bookmarklet « Check images », ou clic droit Inspecter sur chaque image. | F9: Alt présent. Alt vide pour les décoratives. Alt explicite (action attendue) pour les images-liens. Description longue pour les graphiques et schémas complexes.
A10: 2 | B10: Titre de page | C10: 2.4.2 | D10: 8.5, 8.6 | E10: Survoler l'onglet du navigateur, lire la balise <title>. | F10: Titre présent, unique par page, information prioritaire placée en premier (front-loading).
A11: 3 | B11: Titres et hiérarchie | C11: 1.3.1, 2.4.6 | D11: 9.1 | E11: Extension HeadingsMap ou bookmarklet « Check headings ». | F11: Un seul <h1> par page. Niveaux emboîtés sans saut (H1 vers H2 vers H3). Titres balisés <h1> à <h6>, pas seulement stylés en CSS.
A12: 4 | B12: Contraste des couleurs | C12: 1.4.3, 1.4.11 | D12: 3.2, 3.3 | E12: Pipette DevTools, WebAIM Contrast Checker, Colour Contrast Analyser (CCA). | F12: Texte normal : ratio >= 4,5:1. Texte large (18 pt ou 14 pt gras) : ratio >= 3:1. Composants graphiques porteurs d'information : >= 3:1.
A13: 5 | B13: Lien d'évitement | C13: 2.4.1 | D13: 12.7 | E13: Charger la page, appuyer une fois sur Tab. | F13: 1er élément focus = lien « Aller au contenu ». Visible au focus même s'il est masqué par défaut. Ancre valide (#contenu, #main).
A14: 6 | B14: Focus et navigation clavier | C14: 2.4.7, 2.1.1, 2.1.2, 2.4.3 | D14: 10.7, 12.13, 12.14, 10.3 | E14: Cacher la souris. Parcours complet au clavier uniquement (Tab, Maj+Tab, Entrée, Espace, flèches). | F14: Focus visible sur tous les éléments interactifs. Ordre de tabulation logique. Pas de piège clavier. État (coché, développé, sélectionné) annoncé.
A15: 7 | B15: Langue de la page | C15: 3.1.1, 3.1.2 | D15: 8.3, 8.4 | E15: Clic droit « Afficher le code source », chercher <html lang="…">. | F15: Attribut lang présent avec code ISO 639 (fr, en, de…). Passages dans une autre langue balisés <span lang="…">.
A16: 8 | B16: Zoom à 200 % | C16: 1.4.4, 1.4.10 | D16: 10.4, 10.11 | E16: Ctrl + (Cmd + sur Mac) jusqu'à 200 %, parcourir la page complète. | F16: Aucun texte coupé ni superposé. Pas de défilement horizontal forcé. Menus, boutons et formulaires restent utilisables.
A17: 9 | B17: Sous-titres vidéo | C17: 1.2.2 | D17: 4.3, 4.4 | E17: Lancer la vidéo, couper le son, activer les sous-titres (bouton CC). | F17: Sous-titres synchronisés présents. Paroles + informations sonores importantes ((rires), (sonnerie)). Qualité éditoriale (pas auto-générés non relus).
A18: 10 | B18: Transcriptions audio et vidéo | C18: 1.2.1 | D18: 4.1, 4.2 | E18: Chercher un lien « Transcription » ou « Lire le texte » visible près du média. | F18: Transcription accessible à un clic. Complète (paroles + bruits utiles). Navigable (titres, paragraphes).
A19: 11 | B19: Audiodescription | C19: 1.2.3, 1.2.5 | D19: 4.5, 4.6 | E19: Vérifier la présence d'une piste audiodécrite (bouton AD). | F19: AD disponible pour les vidéos informatives à contenu visuel essentiel. Intercalée dans les silences, sans couvrir les dialogues.
A20: 12 | B20: Étiquettes de formulaire | C20: 3.3.2, 1.3.1, 2.5.3 | D20: 11.1, 11.2, 11.3 | E20: Cliquer sur le libellé (le focus doit sauter dans le champ). Tester au lecteur d'écran. | F20: Étiquette visible et persistante. Association <label for="…"> ou aria-labelledby. Placeholder = exemple, jamais étiquette unique. Fieldset/legend pour les groupes (radios, cases).
A21: 13 | B21: Champs obligatoires et erreurs | C21: 3.3.2, 3.3.1, 3.3.3 | D21: 11.10, 11.11 | E21: Soumettre un formulaire incomplet. Écouter l'annonce par le lecteur d'écran. | F21: Obligatoires indiqués textuellement et par astérisque. Légende « * champ obligatoire » présente. Messages d'erreur qui identifient le champ par son libellé.
A24: Synthèse de la page
A25: Conforme (C) | F25: =COUNTIF(G9:G21,"C")
A26: Non conforme (NC) | F26: =COUNTIF(G9:G21,"NC")
A27: Non applicable (NA) | F27: =COUNTIF(G9:G21,"NA")
A28: Taux de conformité Easy Checks | F28: =IFERROR(COUNTIF(G9:G21,"C")/(COUNTIF(G9:G21,"C")+COUNTIF(G9:G21,"NC")),0)
A29: Non-conformités bloquantes | F29: =COUNTIFS(G9:G21,"NC",H9:H21,"Bloquant")
A30: Non-conformités gênantes | F30: =COUNTIFS(G9:G21,"NC",H9:H21,"Gênant")
A31: Non-conformités mineures | F31: =COUNTIFS(G9:G21,"NC",H9:H21,"Mineur")
A33: Top 3 des actions prioritaires
A34: 1.
A35: 2.
A36: 3.
A38: Mon engagement pour demain 9 h

Sheet 12. Liste
A1: Auditeur / auditrice
A2: Date de l'audit
A3: URL de la page auditée
A4: Intitulé de la page | D4: Page type : liste / rubrique / résultats de navigation
A5: Navigateur et version
A6: Outils utilisés
A8: N | B8: Easy Check | C8: WCAG 2.2 | D8: RGAA 4.1.2 | E8: Méthode de test | F8: Ce qu'il faut vérifier | G8: Verdict | H8: Sévérité | I8: Constat | J8: Correctif suggéré | K8: Preuve (URL, sélecteur, capture)
A9: 1 | B9: Alternatives textuelles des images | C9: 1.1.1 | D9: 1.1, 1.2, 1.3, 1.6, 1.7, 1.8, 1.9 | E9: Bookmarklet « Check images », ou clic droit Inspecter sur chaque image. | F9: Alt présent. Alt vide pour les décoratives. Alt explicite (action attendue) pour les images-liens. Description longue pour les graphiques et schémas complexes.
A10: 2 | B10: Titre de page | C10: 2.4.2 | D10: 8.5, 8.6 | E10: Survoler l'onglet du navigateur, lire la balise <title>. | F10: Titre présent, unique par page, information prioritaire placée en premier (front-loading).
